<?xml version="1.0" ?>
<!-- =================================================================================== -->
<!-- |    This document was autogenerated by xacro from robot.urdf.xacro               | -->
<!-- |    EDITING THIS FILE BY HAND IS NOT RECOMMENDED                                 | -->
<!-- =================================================================================== -->
<robot name="robot">
  <!-- Specify some standard inertial calculations https://en.wikipedia.org/wiki/List_of_moments_of_inertia -->
  <!-- These make use of xacro's mathematical functionality -->
  <!-- __________________________________________________________ -->
  <!--                     Robot Description                      -->
  <!-- __________________________________________________________ -->
  <!-- base link -->
  <link name="base">
    <visual>
      <origin xyz="0 0 0"/>
      <geometry>
        <mesh filename="/home/yhofmann/lunarleapersim/OmniLRS/urdf_magnecko/urdf/meshes/body.stl" scale=".0010 .0010 .0010"/>
      </geometry>
      <material name="grey"/>
    </visual>
    <collision>
      <max_contacts>4</max_contacts>
      <origin xyz="0 0 0.044"/>
      <geometry>
        <box size="0.224 0.224 0.088"/>
      </geometry>
      <surface>
        <friction>
          <ode>
            <mu>0.1</mu>
            <mu2>0.1</mu2>
            <slip1>1e-9</slip1>
            <slip2>1e-9</slip2>
          </ode>
        </friction>
        <contact>
          <ode>
            <kp>1e15</kp>
            <kd>1e13</kd>
          </ode>
        </contact>
      </surface>
    </collision>
    <inertial>
      <origin xyz="-0.00582 0.00125 0.0299"/>
      <mass value="4.505"/>
      <inertia ixx="0.0394" ixy="0.0000568" ixz="0.0000382" iyy="0.0430" iyz="0.000321" izz="0.0788"/>
    </inertial>
  </link>
  <!-- Depth Camera -->
  <joint dont_collapse="true" name="camera_joint" type="fixed">
    <parent link="base"/>
    <child link="camera_link"/>
    <origin rpy="0 0 0" xyz="0.0588 0.0175 0.102"/>
  </joint>
  <link name="camera_link">
    <visual>
      <origin rpy="0 0 0" xyz="-0.0125 -0.0175 0"/>
      <geometry>
        <box size="0.025 0.09 0.024"/>
      </geometry>
      <material name="light_grey"/>
    </visual>
  </link>
  <joint dont_collapse="true" name="camera_optical_joint" type="fixed">
    <parent link="camera_link"/>
    <child link="camera_link_optical"/>
    <origin rpy="-1.5707963267948966 0 -1.5707963267948966" xyz="0 0 0"/>
  </joint>
  <link name="camera_link_optical"/>
  <!-- IMU -->
  <joint dont_collapse="true" name="imu_joint" type="fixed">
    <parent link="base"/>
    <child link="imu_link"/>
    <origin rpy="0 3.141592653589793 0" xyz="-0.08 0.08 0.05"/>
  </joint>
  <link name="imu_link">
    </link>
  <joint name="first_arm_yaw" type="revolute">
    <parent link="base"/>
    <child link="first_arm_link"/>
    <origin rpy="0 0 0.7853981633974483" xyz="0.13 0.13 0.0545"/>
    <axis xyz="0 0 1"/>
    <dynamics damping="0.0" friction="0.0"/>
    <limit effort="35.0" lower="-1.5707963267948966" upper="1.5707963267948966" velocity="40.0"/>
  </joint>
  <link name="first_arm_link">
    <visual>
      <origin rpy="0 0 0" xyz="0.0 0.0 0.0"/>
      <geometry>
        <mesh filename="/home/yhofmann/lunarleapersim/OmniLRS/urdf_magnecko/urdf/meshes/hip_FL_BR.stl" scale=".0010 .0010 .0010"/>
      </geometry>
      <material name="aluminum"/>
    </visual>
    <inertial>
      <origin xyz="0.0296 0.01059 0.01002"/>
      <mass value="0.2631"/>
      <inertia ixx="0.000175" ixy="0.0000621" ixz="0.000141" iyy="0.000383" iyz="0.0000432" izz="0.000318"/>
    </inertial>
  </link>
  <joint name="first_arm_pitch" type="revolute">
    <parent link="first_arm_link"/>
    <child link="first_arm"/>
    <origin rpy="0 0 0" xyz="0.06 0.0273 0.02884"/>
    <axis xyz="0 1 0"/>
    <dynamics damping="0.0" friction="0.0"/>
    <limit effort="35.0" lower="-2.35619" upper="1.22173" velocity="40.0"/>
  </joint>
  <link name="first_arm">
    <visual>
      <origin rpy="0.0 0 0" xyz="0 0 0"/>
      <geometry>
        <mesh filename="file:///home/sleuthard/IsaacLab_magnecko/source/magnecko_assets/data/Robots/Magnecko/urdf/xacro/./../meshes/upper_leg.stl" scale=".0010 .0010 .0010"/>
      </geometry>
      <material name="aluminum"/>
    </visual>
    <collision>
      <origin rpy="1.5707963267948966 0 0" xyz="0.18 -0.015 0"/>
      <geometry>
        <cylinder length="0.07" radius="0.036"/>
      </geometry>
    </collision>
    <inertial>
      <origin xyz="0.0899 -0.0279 0.0000748"/>
      <mass value="1.0701"/>
      <inertia ixx="0.000587" ixy="0.00000134" ixz="0.00000331" iyy="0.00756" iyz="0.00000338" izz="0.00753"/>
    </inertial>
  </link>
  <joint name="first_knee_joint" type="revolute">
    <parent link="first_arm"/>
    <child link="first_knee"/>
    <origin rpy="0 0 0" xyz="0.18 0.0 0.0"/>
    <axis xyz="0 1 0"/>
    <dynamics damping="0.0" friction="0.0"/>
    <limit effort="35.0" lower="-2.531" upper="2.531" velocity="40.0"/>
  </joint>
  <link name="first_knee">
    <visual>
      <origin rpy="0.0 0 0" xyz="0 0 0"/>
      <geometry>
        <mesh filename="file:///home/sleuthard/IsaacLab_magnecko/source/magnecko_assets/data/Robots/Magnecko/urdf/xacro/./../meshes/lower_leg_v2.stl" scale=".0010 .0010 .0010"/>
      </geometry>
      <material name="dark_grey"/>
    </visual>
    <collision>
      <origin rpy="0 1.5707963267948966 -0.14835298641951802" xyz="0.11982699999999999 0.002 0"/>
      <geometry>
        <cylinder length="0.16045399999999999" radius="0.016"/>
      </geometry>
    </collision>
    <inertial>
      <origin xyz="0.0450 -0.00333 0.0"/>
      <mass value="0.2009"/>
      <inertia ixx="0.0000645" ixy="-0.0000281" ixz="0.0" iyy="0.00113" iyz="0.0" izz="0.00114"/>
    </inertial>
  </link>
  <joint name="first_ankle_yaw" type="revolute">
    <parent link="first_knee"/>
    <child link="first_ankle_link_1"/>
    <origin rpy="0.0 0.0 0.0" xyz="0.2198 -0.013 -0.0"/>
    <axis xyz="1 0 0"/>
    <dynamics damping="0.01" friction="0.01"/>
    <limit effort="35.0" lower="-1.5707963267948966" upper="1.5707963267948966" velocity="40.0"/>
  </joint>
  <link name="first_ankle_link_1">
    <inertial>
      <origin xyz="0.0 0.0 0.0"/>
      <mass value="0.005"/>
      <inertia ixx="0.0" ixy="0.0" ixz="0.0" iyy="0.0" iyz="0.0" izz="0.0"/>
    </inertial>
    <visual>
      <origin rpy="0 0 0" xyz="0 0 0"/>
      <geometry>
        <mesh filename="file:///home/sleuthard/IsaacLab_magnecko/source/magnecko_assets/data/Robots/Magnecko/urdf/xacro/./../meshes/upper_ankle_joint.stl" scale=".0010 .0010 .0010"/>
      </geometry>
      <material name="light_grey"/>
    </visual>
  </link>
  <joint name="first_ankle_pitch" type="revolute">
    <parent link="first_ankle_link_1"/>
    <child link="first_ankle_link_2"/>
    <origin rpy="0.0 0.0 0.0" xyz="0 0 0"/>
    <axis xyz="0 0 1"/>
    <dynamics damping="0.01" friction="0.01"/>
    <limit effort="35.0" lower="-0.7853981633974483" upper="0.7853981633974483" velocity="40.0"/>
  </joint>
  <link name="first_ankle_link_2">
    <inertial>
      <origin xyz="0.0 0.0 0.0"/>
      <mass value="0.005"/>
      <inertia ixx="0.0" ixy="0.0" ixz="0.0" iyy="0.0" iyz="0.0" izz="0.0"/>
    </inertial>
    <visual>
      <origin rpy="0 0 0" xyz="0 0 0"/>
      <geometry>
        <mesh filename="file:///home/sleuthard/IsaacLab_magnecko/source/magnecko_assets/data/Robots/Magnecko/urdf/xacro/./../meshes/center_ankle_joint.stl" scale=".0010 .0010 .0010"/>
      </geometry>
      <material name="light_grey"/>
    </visual>
  </link>
  <joint name="first_ankle_roll" type="revolute">
    <parent link="first_ankle_link_2"/>
    <child link="first_foot"/>
    <origin rpy="0.0 0.0 0.0" xyz="0 0 0"/>
    <axis xyz="0 1 0"/>
    <dynamics damping="0.01" friction="0.01"/>
    <limit effort="35.0" lower="-0.7853981633974483" upper="0.7853981633974483" velocity="40.0"/>
  </joint>
  <link name="first_foot">
    <collision>
      <origin rpy="0 0 0" xyz="0.0219 0 0"/>
      <geometry>
        <box size="0.02 0.0645 0.0645"/>
      </geometry>
    </collision>
    <visual>
      <origin rpy="0 0 0" xyz="0 0 0"/>
      <geometry>
        <mesh filename="file:///home/sleuthard/IsaacLab_magnecko/source/magnecko_assets/data/Robots/Magnecko/urdf/xacro/./../meshes/foot.stl" scale=".0010 .0010 .0010"/>
      </geometry>
      <material name="light_grey"/>
    </visual>
    <inertial>
      <origin xyz="0.018 0.0 0.0"/>
      <mass value="0.180"/>
      <inertia ixx="0.000105" ixy="0.0" ixz="0.0" iyy="0.00007" iyz="0.0" izz="0.00007"/>
    </inertial>
  </link>
  <joint name="second_arm_yaw" type="revolute">
    <parent link="base"/>
    <child link="second_arm_link"/>
    <origin rpy="0 0 -0.7853981633974483" xyz="0.13 -0.13 0.0545"/>
    <axis xyz="0 0 1"/>
    <dynamics damping="0.0" friction="0.0"/>
    <limit effort="35.0" lower="-1.5707963267948966" upper="1.5707963267948966" velocity="40.0"/>
  </joint>
  <link name="second_arm_link">
    <visual>
      <origin rpy="0 0 0" xyz="0.0 0.0 0.0"/>
      <geometry>
        <mesh filename="file:///home/sleuthard/IsaacLab_magnecko/source/magnecko_assets/data/Robots/Magnecko/urdf/xacro/./../meshes/hip_FR_BL.stl" scale=".0010 .0010 .0010"/>
      </geometry>
      <material name="aluminum"/>
    </visual>
    <inertial>
      <origin xyz="0.0296 -0.01059 0.01002"/>
      <mass value="0.2631"/>
      <inertia ixx="0.000175" ixy="-0.0000621" ixz="0.000141" iyy="0.000383" iyz="-0.0000432" izz="0.000318"/>
    </inertial>
  </link>
  <joint name="second_arm_pitch" type="revolute">
    <parent link="second_arm_link"/>
    <child link="second_arm"/>
    <origin rpy="0 0 0" xyz="0.06 -0.0273 0.02884"/>
    <axis xyz="0 1 0"/>
    <dynamics damping="0.0" friction="0.0"/>
    <limit effort="35.0" lower="-2.35619" upper="1.22173" velocity="40.0"/>
  </joint>
  <link name="second_arm">
    <visual>
      <origin rpy="3.141592653589793 0 0" xyz="0 0 0"/>
      <geometry>
        <mesh filename="file:///home/sleuthard/IsaacLab_magnecko/source/magnecko_assets/data/Robots/Magnecko/urdf/xacro/./../meshes/upper_leg.stl" scale=".0010 .0010 .0010"/>
      </geometry>
      <material name="aluminum"/>
    </visual>
    <collision>
      <origin rpy="1.5707963267948966 0 0" xyz="0.18 0.015 0"/>
      <geometry>
        <cylinder length="0.07" radius="0.036"/>
      </geometry>
    </collision>
    <inertial>
      <origin xyz="0.0899 0.0279 0.0000748"/>
      <mass value="1.0701"/>
      <inertia ixx="0.000587" ixy="-0.00000134" ixz="0.00000331" iyy="0.00756" iyz="-0.00000338" izz="0.00753"/>
    </inertial>
  </link>
  <joint name="second_knee_joint" type="revolute">
    <parent link="second_arm"/>
    <child link="second_knee"/>
    <origin rpy="0 0 0" xyz="0.18 0.0 0.0"/>
    <axis xyz="0 1 0"/>
    <dynamics damping="0.0" friction="0.0"/>
    <limit effort="35.0" lower="-2.531" upper="2.531" velocity="40.0"/>
  </joint>
  <link name="second_knee">
    <visual>
      <origin rpy="3.141592653589793 0 0" xyz="0 0 0"/>
      <geometry>
        <mesh filename="file:///home/sleuthard/IsaacLab_magnecko/source/magnecko_assets/data/Robots/Magnecko/urdf/xacro/./../meshes/lower_leg_v2.stl" scale=".0010 .0010 .0010"/>
      </geometry>
      <material name="dark_grey"/>
    </visual>
    <collision>
      <origin rpy="0 1.5707963267948966 0.14835298641951802" xyz="0.11982699999999999 -0.002 0"/>
      <geometry>
        <cylinder length="0.16045399999999999" radius="0.016"/>
      </geometry>
    </collision>
    <inertial>
      <origin xyz="0.0450 0.00333 0.0"/>
      <mass value="0.2009"/>
      <inertia ixx="0.0000645" ixy="0.0000281" ixz="0.0" iyy="0.00113" iyz="0.0" izz="0.00114"/>
    </inertial>
  </link>
  <joint name="second_ankle_yaw" type="revolute">
    <parent link="second_knee"/>
    <child link="second_ankle_link_1"/>
    <origin rpy="0.0 0.0 0.0" xyz="0.2198 0.013 0.0"/>
    <axis xyz="1 0 0"/>
    <dynamics damping="0.01" friction="0.01"/>
    <limit effort="35.0" lower="-1.5707963267948966" upper="1.5707963267948966" velocity="40.0"/>
  </joint>
  <link name="second_ankle_link_1">
    <inertial>
      <origin xyz="0.0 0.0 0.0"/>
      <mass value="0.005"/>
      <inertia ixx="0.0" ixy="0.0" ixz="0.0" iyy="0.0" iyz="0.0" izz="0.0"/>
    </inertial>
    <visual>
      <origin rpy="0 0 0" xyz="0 0 0"/>
      <geometry>
        <mesh filename="file:///home/sleuthard/IsaacLab_magnecko/source/magnecko_assets/data/Robots/Magnecko/urdf/xacro/./../meshes/upper_ankle_joint.stl" scale=".0010 .0010 .0010"/>
      </geometry>
      <material name="light_grey"/>
    </visual>
  </link>
  <joint name="second_ankle_pitch" type="revolute">
    <parent link="second_ankle_link_1"/>
    <child link="second_ankle_link_2"/>
    <origin rpy="0.0 0.0 0.0" xyz="0 0 0"/>
    <axis xyz="0 0 1"/>
    <dynamics damping="0.01" friction="0.01"/>
    <limit effort="35.0" lower="-0.7853981633974483" upper="0.7853981633974483" velocity="40.0"/>
  </joint>
  <link name="second_ankle_link_2">
    <inertial>
      <origin xyz="0.0 0.0 0.0"/>
      <mass value="0.005"/>
      <inertia ixx="0.0" ixy="0.0" ixz="0.0" iyy="0.0" iyz="0.0" izz="0.0"/>
    </inertial>
    <visual>
      <origin rpy="0 0 0" xyz="0 0 0"/>
      <geometry>
        <mesh filename="file:///home/sleuthard/IsaacLab_magnecko/source/magnecko_assets/data/Robots/Magnecko/urdf/xacro/./../meshes/center_ankle_joint.stl" scale=".0010 .0010 .0010"/>
      </geometry>
      <material name="light_grey"/>
    </visual>
  </link>
  <joint name="second_ankle_roll" type="revolute">
    <parent link="second_ankle_link_2"/>
    <child link="second_foot"/>
    <origin rpy="0.0 0.0 0.0" xyz="0 0 0"/>
    <axis xyz="0 1 0"/>
    <dynamics damping="0.01" friction="0.01"/>
    <limit effort="35.0" lower="-0.7853981633974483" upper="0.7853981633974483" velocity="40.0"/>
  </joint>
  <link name="second_foot">
    <collision>
      <origin rpy="0 0 0" xyz="0.0219 0 0"/>
      <geometry>
        <box size="0.02 0.0645 0.0645"/>
      </geometry>
    </collision>
    <visual>
      <origin rpy="0 0 0" xyz="0 0 0"/>
      <geometry>
        <mesh filename="file:///home/sleuthard/IsaacLab_magnecko/source/magnecko_assets/data/Robots/Magnecko/urdf/xacro/./../meshes/foot.stl" scale=".0010 .0010 .0010"/>
      </geometry>
      <material name="light_grey"/>
    </visual>
    <inertial>
      <origin xyz="0.018 0.0 0.0"/>
      <mass value="0.180"/>
      <inertia ixx="0.000105" ixy="0.0" ixz="0.0" iyy="0.00007" iyz="0.0" izz="0.00007"/>
    </inertial>
  </link>
  <joint name="third_arm_yaw" type="revolute">
    <parent link="base"/>
    <child link="third_arm_link"/>
    <origin rpy="0 0 -2.356194490192345" xyz="-0.13 -0.13 0.0545"/>
    <axis xyz="0 0 1"/>
    <dynamics damping="0.0" friction="0.0"/>
    <limit effort="35.0" lower="-1.5707963267948966" upper="1.5707963267948966" velocity="40.0"/>
  </joint>
  <link name="third_arm_link">
    <visual>
      <origin rpy="0 0 0" xyz="0.0 0.0 0.0"/>
      <geometry>
        <mesh filename="file:///home/sleuthard/IsaacLab_magnecko/source/magnecko_assets/data/Robots/Magnecko/urdf/xacro/./../meshes/hip_FL_BR.stl" scale=".0010 .0010 .0010"/>
      </geometry>
      <material name="aluminum"/>
    </visual>
    <inertial>
      <origin xyz="0.0296 0.01059 0.01002"/>
      <mass value="0.2631"/>
      <inertia ixx="0.000175" ixy="0.0000621" ixz="0.000141" iyy="0.000383" iyz="0.0000432" izz="0.000318"/>
    </inertial>
  </link>
  <joint name="third_arm_pitch" type="revolute">
    <parent link="third_arm_link"/>
    <child link="third_arm"/>
    <origin rpy="0 0 0" xyz="0.06 0.0273 0.02884"/>
    <axis xyz="0 1 0"/>
    <dynamics damping="0.0" friction="0.0"/>
    <limit effort="35.0" lower="-2.35619" upper="1.22173" velocity="40.0"/>
  </joint>
  <link name="third_arm">
    <visual>
      <origin rpy="0.0 0 0" xyz="0 0 0"/>
      <geometry>
        <mesh filename="file:///home/sleuthard/IsaacLab_magnecko/source/magnecko_assets/data/Robots/Magnecko/urdf/xacro/./../meshes/upper_leg.stl" scale=".0010 .0010 .0010"/>
      </geometry>
      <material name="aluminum"/>
    </visual>
    <collision>
      <origin rpy="1.5707963267948966 0 0" xyz="0.18 -0.015 0"/>
      <geometry>
        <cylinder length="0.07" radius="0.036"/>
      </geometry>
    </collision>
    <inertial>
      <origin xyz="0.0899 -0.0279 0.0000748"/>
      <mass value="1.0701"/>
      <inertia ixx="0.000587" ixy="0.00000134" ixz="0.00000331" iyy="0.00756" iyz="0.00000338" izz="0.00753"/>
    </inertial>
  </link>
  <joint name="third_knee_joint" type="revolute">
    <parent link="third_arm"/>
    <child link="third_knee"/>
    <origin rpy="0 0 0" xyz="0.18 0.0 0.0"/>
    <axis xyz="0 1 0"/>
    <dynamics damping="0.0" friction="0.0"/>
    <limit effort="35.0" lower="-2.531" upper="2.531" velocity="40.0"/>
  </joint>
  <link name="third_knee">
    <visual>
      <origin rpy="0.0 0 0" xyz="0 0 0"/>
      <geometry>
        <mesh filename="file:///home/sleuthard/IsaacLab_magnecko/source/magnecko_assets/data/Robots/Magnecko/urdf/xacro/./../meshes/lower_leg_v2.stl" scale=".0010 .0010 .0010"/>
      </geometry>
      <material name="dark_grey"/>
    </visual>
    <collision>
      <origin rpy="0 1.5707963267948966 -0.14835298641951802" xyz="0.11982699999999999 0.002 0"/>
      <geometry>
        <cylinder length="0.16045399999999999" radius="0.016"/>
      </geometry>
    </collision>
    <inertial>
      <origin xyz="0.0450 -0.00333 0.0"/>
      <mass value="0.2009"/>
      <inertia ixx="0.0000645" ixy="-0.0000281" ixz="0.0" iyy="0.00113" iyz="0.0" izz="0.00114"/>
    </inertial>
  </link>
  <joint name="third_ankle_yaw" type="revolute">
    <parent link="third_knee"/>
    <child link="third_ankle_link_1"/>
    <origin rpy="0.0 0.0 0.0" xyz="0.2198 -0.013 -0.0"/>
    <axis xyz="1 0 0"/>
    <dynamics damping="0.01" friction="0.01"/>
    <limit effort="35.0" lower="-1.5707963267948966" upper="1.5707963267948966" velocity="40.0"/>
  </joint>
  <link name="third_ankle_link_1">
    <inertial>
      <origin xyz="0.0 0.0 0.0"/>
      <mass value="0.005"/>
      <inertia ixx="0.0" ixy="0.0" ixz="0.0" iyy="0.0" iyz="0.0" izz="0.0"/>
    </inertial>
    <visual>
      <origin rpy="0 0 0" xyz="0 0 0"/>
      <geometry>
        <mesh filename="file:///home/sleuthard/IsaacLab_magnecko/source/magnecko_assets/data/Robots/Magnecko/urdf/xacro/./../meshes/upper_ankle_joint.stl" scale=".0010 .0010 .0010"/>
      </geometry>
      <material name="light_grey"/>
    </visual>
  </link>
  <joint name="third_ankle_pitch" type="revolute">
    <parent link="third_ankle_link_1"/>
    <child link="third_ankle_link_2"/>
    <origin rpy="0.0 0.0 0.0" xyz="0 0 0"/>
    <axis xyz="0 0 1"/>
    <dynamics damping="0.01" friction="0.01"/>
    <limit effort="35.0" lower="-0.7853981633974483" upper="0.7853981633974483" velocity="40.0"/>
  </joint>
  <link name="third_ankle_link_2">
    <inertial>
      <origin xyz="0.0 0.0 0.0"/>
      <mass value="0.005"/>
      <inertia ixx="0.0" ixy="0.0" ixz="0.0" iyy="0.0" iyz="0.0" izz="0.0"/>
    </inertial>
    <visual>
      <origin rpy="0 0 0" xyz="0 0 0"/>
      <geometry>
        <mesh filename="file:///home/sleuthard/IsaacLab_magnecko/source/magnecko_assets/data/Robots/Magnecko/urdf/xacro/./../meshes/center_ankle_joint.stl" scale=".0010 .0010 .0010"/>
      </geometry>
      <material name="light_grey"/>
    </visual>
  </link>
  <joint name="third_ankle_roll" type="revolute">
    <parent link="third_ankle_link_2"/>
    <child link="third_foot"/>
    <origin rpy="0.0 0.0 0.0" xyz="0 0 0"/>
    <axis xyz="0 1 0"/>
    <dynamics damping="0.01" friction="0.01"/>
    <limit effort="35.0" lower="-0.7853981633974483" upper="0.7853981633974483" velocity="40.0"/>
  </joint>
  <link name="third_foot">
    <collision>
      <origin rpy="0 0 0" xyz="0.0219 0 0"/>
      <geometry>
        <box size="0.02 0.0645 0.0645"/>
      </geometry>
    </collision>
    <visual>
      <origin rpy="0 0 0" xyz="0 0 0"/>
      <geometry>
        <mesh filename="file:///home/sleuthard/IsaacLab_magnecko/source/magnecko_assets/data/Robots/Magnecko/urdf/xacro/./../meshes/foot.stl" scale=".0010 .0010 .0010"/>
      </geometry>
      <material name="light_grey"/>
    </visual>
    <inertial>
      <origin xyz="0.018 0.0 0.0"/>
      <mass value="0.180"/>
      <inertia ixx="0.000105" ixy="0.0" ixz="0.0" iyy="0.00007" iyz="0.0" izz="0.00007"/>
    </inertial>
  </link>
  <joint name="fourth_arm_yaw" type="revolute">
    <parent link="base"/>
    <child link="fourth_arm_link"/>
    <origin rpy="0 0 -3.9269908169872414" xyz="-0.13 0.13 0.0545"/>
    <axis xyz="0 0 1"/>
    <dynamics damping="0.0" friction="0.0"/>
    <limit effort="35.0" lower="-1.5707963267948966" upper="1.5707963267948966" velocity="40.0"/>
  </joint>
  <link name="fourth_arm_link">
    <visual>
      <origin rpy="0 0 0" xyz="0.0 0.0 0.0"/>
      <geometry>
        <mesh filename="file:///home/sleuthard/IsaacLab_magnecko/source/magnecko_assets/data/Robots/Magnecko/urdf/xacro/./../meshes/hip_FR_BL.stl" scale=".0010 .0010 .0010"/>
      </geometry>
      <material name="aluminum"/>
    </visual>
    <inertial>
      <origin xyz="0.0296 -0.01059 0.01002"/>
      <mass value="0.2631"/>
      <inertia ixx="0.000175" ixy="-0.0000621" ixz="0.000141" iyy="0.000383" iyz="-0.0000432" izz="0.000318"/>
    </inertial>
  </link>
  <joint name="fourth_arm_pitch" type="revolute">
    <parent link="fourth_arm_link"/>
    <child link="fourth_arm"/>
    <origin rpy="0 0 0" xyz="0.06 -0.0273 0.02884"/>
    <axis xyz="0 1 0"/>
    <dynamics damping="0.0" friction="0.0"/>
    <limit effort="35.0" lower="-2.35619" upper="1.22173" velocity="40.0"/>
  </joint>
  <link name="fourth_arm">
    <visual>
      <origin rpy="3.141592653589793 0 0" xyz="0 0 0"/>
      <geometry>
        <mesh filename="file:///home/sleuthard/IsaacLab_magnecko/source/magnecko_assets/data/Robots/Magnecko/urdf/xacro/./../meshes/upper_leg.stl" scale=".0010 .0010 .0010"/>
      </geometry>
      <material name="aluminum"/>
    </visual>
    <collision>
      <origin rpy="1.5707963267948966 0 0" xyz="0.18 0.015 0"/>
      <geometry>
        <cylinder length="0.07" radius="0.036"/>
      </geometry>
    </collision>
    <inertial>
      <origin xyz="0.0899 0.0279 0.0000748"/>
      <mass value="1.0701"/>
      <inertia ixx="0.000587" ixy="-0.00000134" ixz="0.00000331" iyy="0.00756" iyz="-0.00000338" izz="0.00753"/>
    </inertial>
  </link>
  <joint name="fourth_knee_joint" type="revolute">
    <parent link="fourth_arm"/>
    <child link="fourth_knee"/>
    <origin rpy="0 0 0" xyz="0.18 0.0 0.0"/>
    <axis xyz="0 1 0"/>
    <dynamics damping="0.0" friction="0.0"/>
    <limit effort="35.0" lower="-2.531" upper="2.531" velocity="40.0"/>
  </joint>
  <link name="fourth_knee">
    <visual>
      <origin rpy="3.141592653589793 0 0" xyz="0 0 0"/>
      <geometry>
        <mesh filename="file:///home/sleuthard/IsaacLab_magnecko/source/magnecko_assets/data/Robots/Magnecko/urdf/xacro/./../meshes/lower_leg_v2.stl" scale=".0010 .0010 .0010"/>
      </geometry>
      <material name="dark_grey"/>
    </visual>
    <collision>
      <origin rpy="0 1.5707963267948966 0.14835298641951802" xyz="0.11982699999999999 -0.002 0"/>
      <geometry>
        <cylinder length="0.16045399999999999" radius="0.016"/>
      </geometry>
    </collision>
    <inertial>
      <origin xyz="0.0450 0.00333 0.0"/>
      <mass value="0.2009"/>
      <inertia ixx="0.0000645" ixy="0.0000281" ixz="0.0" iyy="0.00113" iyz="0.0" izz="0.00114"/>
    </inertial>
  </link>
  <joint name="fourth_ankle_yaw" type="revolute">
    <parent link="fourth_knee"/>
    <child link="fourth_ankle_link_1"/>
    <origin rpy="0.0 0.0 0.0" xyz="0.2198 0.013 0.0"/>
    <axis xyz="1 0 0"/>
    <dynamics damping="0.01" friction="0.01"/>
    <limit effort="35.0" lower="-1.5707963267948966" upper="1.5707963267948966" velocity="40.0"/>
  </joint>
  <link name="fourth_ankle_link_1">
    <inertial>
      <origin xyz="0.0 0.0 0.0"/>
      <mass value="0.005"/>
      <inertia ixx="0.0" ixy="0.0" ixz="0.0" iyy="0.0" iyz="0.0" izz="0.0"/>
    </inertial>
    <visual>
      <origin rpy="0 0 0" xyz="0 0 0"/>
      <geometry>
        <mesh filename="file:///home/sleuthard/IsaacLab_magnecko/source/magnecko_assets/data/Robots/Magnecko/urdf/xacro/./../meshes/upper_ankle_joint.stl" scale=".0010 .0010 .0010"/>
      </geometry>
      <material name="light_grey"/>
    </visual>
  </link>
  <joint name="fourth_ankle_pitch" type="revolute">
    <parent link="fourth_ankle_link_1"/>
    <child link="fourth_ankle_link_2"/>
    <origin rpy="0.0 0.0 0.0" xyz="0 0 0"/>
    <axis xyz="0 0 1"/>
    <dynamics damping="0.01" friction="0.01"/>
    <limit effort="35.0" lower="-0.7853981633974483" upper="0.7853981633974483" velocity="40.0"/>
  </joint>
  <link name="fourth_ankle_link_2">
    <inertial>
      <origin xyz="0.0 0.0 0.0"/>
      <mass value="0.005"/>
      <inertia ixx="0.0" ixy="0.0" ixz="0.0" iyy="0.0" iyz="0.0" izz="0.0"/>
    </inertial>
    <visual>
      <origin rpy="0 0 0" xyz="0 0 0"/>
      <geometry>
        <mesh filename="file:///home/sleuthard/IsaacLab_magnecko/source/magnecko_assets/data/Robots/Magnecko/urdf/xacro/./../meshes/center_ankle_joint.stl" scale=".0010 .0010 .0010"/>
      </geometry>
      <material name="light_grey"/>
    </visual>
  </link>
  <joint name="fourth_ankle_roll" type="revolute">
    <parent link="fourth_ankle_link_2"/>
    <child link="fourth_foot"/>
    <origin rpy="0.0 0.0 0.0" xyz="0 0 0"/>
    <axis xyz="0 1 0"/>
    <dynamics damping="0.01" friction="0.01"/>
    <limit effort="35.0" lower="-0.7853981633974483" upper="0.7853981633974483" velocity="40.0"/>
  </joint>
  <link name="fourth_foot">
    <collision>
      <origin rpy="0 0 0" xyz="0.0219 0 0"/>
      <geometry>
        <box size="0.02 0.0645 0.0645"/>
      </geometry>
    </collision>
    <visual>
      <origin rpy="0 0 0" xyz="0 0 0"/>
      <geometry>
        <mesh filename="file:///home/sleuthard/IsaacLab_magnecko/source/magnecko_assets/data/Robots/Magnecko/urdf/xacro/./../meshes/foot.stl" scale=".0010 .0010 .0010"/>
      </geometry>
      <material name="light_grey"/>
    </visual>
    <inertial>
      <origin xyz="0.018 0.0 0.0"/>
      <mass value="0.180"/>
      <inertia ixx="0.000105" ixy="0.0" ixz="0.0" iyy="0.00007" iyz="0.0" izz="0.00007"/>
    </inertial>
  </link>
  <material name="black">
    <color rgba="0.0 0.0 0.0 1.0"/>
  </material>
  <material name="blue">
    <color rgba="0.0 0.0 0.8 1.0"/>
  </material>
  <material name="green">
    <color rgba="0.0 0.8 0.0 1.0"/>
  </material>
  <material name="grey">
    <color rgba="0.05 0.05 0.05 1.0"/>
  </material>
  <material name="orange">
    <color rgba="1.0 0.4235294117647059 0.0392156862745098 1.0"/>
  </material>
  <material name="brown">
    <color rgba="0.8705882352941177 0.8117647058823529 0.7647058823529411 1.0"/>
  </material>
  <material name="red">
    <color rgba="0.8 0.0 0.0 1.0"/>
  </material>
  <material name="yellow">
    <color rgba="1.0 1.0 0.0 1.0"/>
  </material>
  <material name="white">
    <color rgba="1.0 1.0 1.0 1.0"/>
  </material>
  <material name="dark_grey">
    <color rgba="0.02 0.02 0.02 1.0"/>
  </material>
  <material name="light_grey">
    <color rgba="0.15 0.15 0.15 1.0"/>
  </material>
  <material name="aluminum">
    <color rgba="0.3 0.3 0.3 1.0"/>
  </material>
</robot>
